## 1.7 Panic

Podemos recuperarnos de errores tipo panic llamando a la función
recover. **recover solo puede usarse dentro de una función con defer
directa**, es decir no puede estar dentro de una función que llame a
otra función, incluso si la función original tiene el atributo defer.

``` go
defer func() {
        fmt.Println("recovered:",recover())
    }()
```

